[2025-08-09 16:21:30.141] [ICT_Dashboard_BlackBox_error] [CRITICAL] [log_critical_error:306] CRITICAL_ERROR | _update_overview_rich_attempt_1 | AttributeError: 'ICTEnterpriseApp' object has no attribute '_get_system_stats'
[2025-08-09 16:21:30.154] [ICT_Dashboard_BlackBox_error] [CRITICAL] [log_critical_error:307] STACK_TRACE | Traceback (most recent call last):
  File "c:\Users\v_jac\Desktop\itc engine v5.0\ict-engine-v6.0-enterprise-sic\tests\ict_enterprise_dashboard_fixed.py", line 464, in _update_overview
    system_stats = self._get_system_stats()
                   ^^^^^^^^^^^^^^^^^^^^^^
AttributeError: 'ICTEnterpriseApp' object has no attribute '_get_system_stats'

[2025-08-09 16:21:30.165] [ICT_Dashboard_BlackBox_error] [CRITICAL] [log_critical_error:306] CRITICAL_ERROR | _update_overview_rich_attempt_2 | AttributeError: 'ICTEnterpriseApp' object has no attribute '_get_system_stats'
[2025-08-09 16:21:30.175] [ICT_Dashboard_BlackBox_error] [CRITICAL] [log_critical_error:307] STACK_TRACE | Traceback (most recent call last):
  File "c:\Users\v_jac\Desktop\itc engine v5.0\ict-engine-v6.0-enterprise-sic\tests\ict_enterprise_dashboard_fixed.py", line 464, in _update_overview
    system_stats = self._get_system_stats()
                   ^^^^^^^^^^^^^^^^^^^^^^
AttributeError: 'ICTEnterpriseApp' object has no attribute '_get_system_stats'

[2025-08-09 16:21:30.185] [ICT_Dashboard_BlackBox_error] [CRITICAL] [log_critical_error:306] CRITICAL_ERROR | _update_overview_rich_attempt_3 | AttributeError: 'ICTEnterpriseApp' object has no attribute '_get_system_stats'
[2025-08-09 16:21:30.201] [ICT_Dashboard_BlackBox_error] [CRITICAL] [log_critical_error:307] STACK_TRACE | Traceback (most recent call last):
  File "c:\Users\v_jac\Desktop\itc engine v5.0\ict-engine-v6.0-enterprise-sic\tests\ict_enterprise_dashboard_fixed.py", line 464, in _update_overview
    system_stats = self._get_system_stats()
                   ^^^^^^^^^^^^^^^^^^^^^^
AttributeError: 'ICTEnterpriseApp' object has no attribute '_get_system_stats'

[2025-08-09 16:21:30.214] [ICT_Dashboard_BlackBox_error] [CRITICAL] [log_critical_error:306] CRITICAL_ERROR | _update_overview_rich | AttributeError: 'ICTEnterpriseApp' object has no attribute '_get_system_stats'
[2025-08-09 16:21:30.229] [ICT_Dashboard_BlackBox_error] [CRITICAL] [log_critical_error:307] STACK_TRACE | Traceback (most recent call last):
  File "c:\Users\v_jac\Desktop\itc engine v5.0\ict-engine-v6.0-enterprise-sic\tests\ict_enterprise_dashboard_fixed.py", line 464, in _update_overview
    system_stats = self._get_system_stats()
                   ^^^^^^^^^^^^^^^^^^^^^^
AttributeError: 'ICTEnterpriseApp' object has no attribute '_get_system_stats'

[2025-08-09 16:21:30.260] [ICT_Dashboard_BlackBox_error] [CRITICAL] [log_critical_error:306] CRITICAL_ERROR | _update_overview_rich_attempt_1 | AttributeError: 'ICTEnterpriseApp' object has no attribute '_get_system_stats'
[2025-08-09 16:21:30.274] [ICT_Dashboard_BlackBox_error] [CRITICAL] [log_critical_error:307] STACK_TRACE | Traceback (most recent call last):
  File "c:\Users\v_jac\Desktop\itc engine v5.0\ict-engine-v6.0-enterprise-sic\tests\ict_enterprise_dashboard_fixed.py", line 464, in _update_overview
    system_stats = self._get_system_stats()
                   ^^^^^^^^^^^^^^^^^^^^^^
AttributeError: 'ICTEnterpriseApp' object has no attribute '_get_system_stats'

[2025-08-09 16:21:30.288] [ICT_Dashboard_BlackBox_error] [CRITICAL] [log_critical_error:306] CRITICAL_ERROR | _update_overview_rich_attempt_2 | AttributeError: 'ICTEnterpriseApp' object has no attribute '_get_system_stats'
[2025-08-09 16:21:30.302] [ICT_Dashboard_BlackBox_error] [CRITICAL] [log_critical_error:307] STACK_TRACE | Traceback (most recent call last):
  File "c:\Users\v_jac\Desktop\itc engine v5.0\ict-engine-v6.0-enterprise-sic\tests\ict_enterprise_dashboard_fixed.py", line 464, in _update_overview
    system_stats = self._get_system_stats()
                   ^^^^^^^^^^^^^^^^^^^^^^
AttributeError: 'ICTEnterpriseApp' object has no attribute '_get_system_stats'

[2025-08-09 16:21:30.318] [ICT_Dashboard_BlackBox_error] [CRITICAL] [log_critical_error:306] CRITICAL_ERROR | _update_overview_rich_attempt_3 | AttributeError: 'ICTEnterpriseApp' object has no attribute '_get_system_stats'
[2025-08-09 16:21:30.332] [ICT_Dashboard_BlackBox_error] [CRITICAL] [log_critical_error:307] STACK_TRACE | Traceback (most recent call last):
  File "c:\Users\v_jac\Desktop\itc engine v5.0\ict-engine-v6.0-enterprise-sic\tests\ict_enterprise_dashboard_fixed.py", line 464, in _update_overview
    system_stats = self._get_system_stats()
                   ^^^^^^^^^^^^^^^^^^^^^^
AttributeError: 'ICTEnterpriseApp' object has no attribute '_get_system_stats'

[2025-08-09 16:21:30.342] [ICT_Dashboard_BlackBox_error] [CRITICAL] [log_critical_error:306] CRITICAL_ERROR | _update_overview_rich | AttributeError: 'ICTEnterpriseApp' object has no attribute '_get_system_stats'
[2025-08-09 16:21:30.351] [ICT_Dashboard_BlackBox_error] [CRITICAL] [log_critical_error:307] STACK_TRACE | Traceback (most recent call last):
  File "c:\Users\v_jac\Desktop\itc engine v5.0\ict-engine-v6.0-enterprise-sic\tests\ict_enterprise_dashboard_fixed.py", line 464, in _update_overview
    system_stats = self._get_system_stats()
                   ^^^^^^^^^^^^^^^^^^^^^^
AttributeError: 'ICTEnterpriseApp' object has no attribute '_get_system_stats'

[2025-08-09 16:21:30.487] [ICT_Dashboard_BlackBox_error] [CRITICAL] [log_critical_error:306] CRITICAL_ERROR | _update_overview_rich_attempt_1 | AttributeError: 'ICTEnterpriseApp' object has no attribute '_get_system_stats'
[2025-08-09 16:21:30.499] [ICT_Dashboard_BlackBox_error] [CRITICAL] [log_critical_error:307] STACK_TRACE | Traceback (most recent call last):
  File "c:\Users\v_jac\Desktop\itc engine v5.0\ict-engine-v6.0-enterprise-sic\tests\ict_enterprise_dashboard_fixed.py", line 464, in _update_overview
    system_stats = self._get_system_stats()
                   ^^^^^^^^^^^^^^^^^^^^^^
AttributeError: 'ICTEnterpriseApp' object has no attribute '_get_system_stats'

[2025-08-09 16:21:30.509] [ICT_Dashboard_BlackBox_error] [CRITICAL] [log_critical_error:306] CRITICAL_ERROR | _update_overview_rich_attempt_2 | AttributeError: 'ICTEnterpriseApp' object has no attribute '_get_system_stats'
[2025-08-09 16:21:30.518] [ICT_Dashboard_BlackBox_error] [CRITICAL] [log_critical_error:307] STACK_TRACE | Traceback (most recent call last):
  File "c:\Users\v_jac\Desktop\itc engine v5.0\ict-engine-v6.0-enterprise-sic\tests\ict_enterprise_dashboard_fixed.py", line 464, in _update_overview
    system_stats = self._get_system_stats()
                   ^^^^^^^^^^^^^^^^^^^^^^
AttributeError: 'ICTEnterpriseApp' object has no attribute '_get_system_stats'

[2025-08-09 16:21:30.527] [ICT_Dashboard_BlackBox_error] [CRITICAL] [log_critical_error:306] CRITICAL_ERROR | _update_overview_rich_attempt_3 | AttributeError: 'ICTEnterpriseApp' object has no attribute '_get_system_stats'
[2025-08-09 16:21:30.537] [ICT_Dashboard_BlackBox_error] [CRITICAL] [log_critical_error:307] STACK_TRACE | Traceback (most recent call last):
  File "c:\Users\v_jac\Desktop\itc engine v5.0\ict-engine-v6.0-enterprise-sic\tests\ict_enterprise_dashboard_fixed.py", line 464, in _update_overview
    system_stats = self._get_system_stats()
                   ^^^^^^^^^^^^^^^^^^^^^^
AttributeError: 'ICTEnterpriseApp' object has no attribute '_get_system_stats'

[2025-08-09 16:21:30.547] [ICT_Dashboard_BlackBox_error] [CRITICAL] [log_critical_error:306] CRITICAL_ERROR | _update_overview_rich | AttributeError: 'ICTEnterpriseApp' object has no attribute '_get_system_stats'
[2025-08-09 16:21:30.556] [ICT_Dashboard_BlackBox_error] [CRITICAL] [log_critical_error:307] STACK_TRACE | Traceback (most recent call last):
  File "c:\Users\v_jac\Desktop\itc engine v5.0\ict-engine-v6.0-enterprise-sic\tests\ict_enterprise_dashboard_fixed.py", line 464, in _update_overview
    system_stats = self._get_system_stats()
                   ^^^^^^^^^^^^^^^^^^^^^^
AttributeError: 'ICTEnterpriseApp' object has no attribute '_get_system_stats'

[2025-08-09 16:21:30.686] [ICT_Dashboard_BlackBox_error] [CRITICAL] [log_critical_error:306] CRITICAL_ERROR | _update_overview_rich_attempt_1 | AttributeError: 'ICTEnterpriseApp' object has no attribute '_get_system_stats'
[2025-08-09 16:21:30.699] [ICT_Dashboard_BlackBox_error] [CRITICAL] [log_critical_error:307] STACK_TRACE | Traceback (most recent call last):
  File "c:\Users\v_jac\Desktop\itc engine v5.0\ict-engine-v6.0-enterprise-sic\tests\ict_enterprise_dashboard_fixed.py", line 464, in _update_overview
    system_stats = self._get_system_stats()
                   ^^^^^^^^^^^^^^^^^^^^^^
AttributeError: 'ICTEnterpriseApp' object has no attribute '_get_system_stats'

[2025-08-09 16:21:30.711] [ICT_Dashboard_BlackBox_error] [CRITICAL] [log_critical_error:306] CRITICAL_ERROR | _update_overview_rich_attempt_2 | AttributeError: 'ICTEnterpriseApp' object has no attribute '_get_system_stats'
[2025-08-09 16:21:30.726] [ICT_Dashboard_BlackBox_error] [CRITICAL] [log_critical_error:307] STACK_TRACE | Traceback (most recent call last):
  File "c:\Users\v_jac\Desktop\itc engine v5.0\ict-engine-v6.0-enterprise-sic\tests\ict_enterprise_dashboard_fixed.py", line 464, in _update_overview
    system_stats = self._get_system_stats()
                   ^^^^^^^^^^^^^^^^^^^^^^
AttributeError: 'ICTEnterpriseApp' object has no attribute '_get_system_stats'

[2025-08-09 16:21:30.735] [ICT_Dashboard_BlackBox_error] [CRITICAL] [log_critical_error:306] CRITICAL_ERROR | _update_overview_rich_attempt_3 | AttributeError: 'ICTEnterpriseApp' object has no attribute '_get_system_stats'
[2025-08-09 16:21:30.744] [ICT_Dashboard_BlackBox_error] [CRITICAL] [log_critical_error:307] STACK_TRACE | Traceback (most recent call last):
  File "c:\Users\v_jac\Desktop\itc engine v5.0\ict-engine-v6.0-enterprise-sic\tests\ict_enterprise_dashboard_fixed.py", line 464, in _update_overview
    system_stats = self._get_system_stats()
                   ^^^^^^^^^^^^^^^^^^^^^^
AttributeError: 'ICTEnterpriseApp' object has no attribute '_get_system_stats'

[2025-08-09 16:21:30.753] [ICT_Dashboard_BlackBox_error] [CRITICAL] [log_critical_error:306] CRITICAL_ERROR | _update_overview_rich | AttributeError: 'ICTEnterpriseApp' object has no attribute '_get_system_stats'
[2025-08-09 16:21:30.763] [ICT_Dashboard_BlackBox_error] [CRITICAL] [log_critical_error:307] STACK_TRACE | Traceback (most recent call last):
  File "c:\Users\v_jac\Desktop\itc engine v5.0\ict-engine-v6.0-enterprise-sic\tests\ict_enterprise_dashboard_fixed.py", line 464, in _update_overview
    system_stats = self._get_system_stats()
                   ^^^^^^^^^^^^^^^^^^^^^^
AttributeError: 'ICTEnterpriseApp' object has no attribute '_get_system_stats'

[2025-08-09 16:21:30.902] [ICT_Dashboard_BlackBox_error] [CRITICAL] [log_critical_error:306] CRITICAL_ERROR | _update_overview_rich_attempt_1 | AttributeError: 'ICTEnterpriseApp' object has no attribute '_get_system_stats'
[2025-08-09 16:21:30.917] [ICT_Dashboard_BlackBox_error] [CRITICAL] [log_critical_error:307] STACK_TRACE | Traceback (most recent call last):
  File "c:\Users\v_jac\Desktop\itc engine v5.0\ict-engine-v6.0-enterprise-sic\tests\ict_enterprise_dashboard_fixed.py", line 464, in _update_overview
    system_stats = self._get_system_stats()
                   ^^^^^^^^^^^^^^^^^^^^^^
AttributeError: 'ICTEnterpriseApp' object has no attribute '_get_system_stats'

[2025-08-09 16:21:30.932] [ICT_Dashboard_BlackBox_error] [CRITICAL] [log_critical_error:306] CRITICAL_ERROR | _update_overview_rich_attempt_2 | AttributeError: 'ICTEnterpriseApp' object has no attribute '_get_system_stats'
[2025-08-09 16:21:30.946] [ICT_Dashboard_BlackBox_error] [CRITICAL] [log_critical_error:307] STACK_TRACE | Traceback (most recent call last):
  File "c:\Users\v_jac\Desktop\itc engine v5.0\ict-engine-v6.0-enterprise-sic\tests\ict_enterprise_dashboard_fixed.py", line 464, in _update_overview
    system_stats = self._get_system_stats()
                   ^^^^^^^^^^^^^^^^^^^^^^
AttributeError: 'ICTEnterpriseApp' object has no attribute '_get_system_stats'

[2025-08-09 16:21:30.959] [ICT_Dashboard_BlackBox_error] [CRITICAL] [log_critical_error:306] CRITICAL_ERROR | _update_overview_rich_attempt_3 | AttributeError: 'ICTEnterpriseApp' object has no attribute '_get_system_stats'
[2025-08-09 16:21:30.973] [ICT_Dashboard_BlackBox_error] [CRITICAL] [log_critical_error:307] STACK_TRACE | Traceback (most recent call last):
  File "c:\Users\v_jac\Desktop\itc engine v5.0\ict-engine-v6.0-enterprise-sic\tests\ict_enterprise_dashboard_fixed.py", line 464, in _update_overview
    system_stats = self._get_system_stats()
                   ^^^^^^^^^^^^^^^^^^^^^^
AttributeError: 'ICTEnterpriseApp' object has no attribute '_get_system_stats'

[2025-08-09 16:21:30.982] [ICT_Dashboard_BlackBox_error] [CRITICAL] [log_critical_error:306] CRITICAL_ERROR | _update_overview_rich | AttributeError: 'ICTEnterpriseApp' object has no attribute '_get_system_stats'
[2025-08-09 16:21:30.991] [ICT_Dashboard_BlackBox_error] [CRITICAL] [log_critical_error:307] STACK_TRACE | Traceback (most recent call last):
  File "c:\Users\v_jac\Desktop\itc engine v5.0\ict-engine-v6.0-enterprise-sic\tests\ict_enterprise_dashboard_fixed.py", line 464, in _update_overview
    system_stats = self._get_system_stats()
                   ^^^^^^^^^^^^^^^^^^^^^^
AttributeError: 'ICTEnterpriseApp' object has no attribute '_get_system_stats'

[2025-08-09 16:21:31.063] [ICT_Dashboard_BlackBox_error] [CRITICAL] [log_critical_error:306] CRITICAL_ERROR | _update_overview_rich_attempt_1 | AttributeError: 'ICTEnterpriseApp' object has no attribute '_get_system_stats'
[2025-08-09 16:21:31.074] [ICT_Dashboard_BlackBox_error] [CRITICAL] [log_critical_error:307] STACK_TRACE | Traceback (most recent call last):
  File "c:\Users\v_jac\Desktop\itc engine v5.0\ict-engine-v6.0-enterprise-sic\tests\ict_enterprise_dashboard_fixed.py", line 464, in _update_overview
    system_stats = self._get_system_stats()
                   ^^^^^^^^^^^^^^^^^^^^^^
AttributeError: 'ICTEnterpriseApp' object has no attribute '_get_system_stats'

[2025-08-09 16:21:31.084] [ICT_Dashboard_BlackBox_error] [CRITICAL] [log_critical_error:306] CRITICAL_ERROR | _update_overview_rich_attempt_2 | AttributeError: 'ICTEnterpriseApp' object has no attribute '_get_system_stats'
[2025-08-09 16:21:31.093] [ICT_Dashboard_BlackBox_error] [CRITICAL] [log_critical_error:307] STACK_TRACE | Traceback (most recent call last):
  File "c:\Users\v_jac\Desktop\itc engine v5.0\ict-engine-v6.0-enterprise-sic\tests\ict_enterprise_dashboard_fixed.py", line 464, in _update_overview
    system_stats = self._get_system_stats()
                   ^^^^^^^^^^^^^^^^^^^^^^
AttributeError: 'ICTEnterpriseApp' object has no attribute '_get_system_stats'

[2025-08-09 16:21:31.102] [ICT_Dashboard_BlackBox_error] [CRITICAL] [log_critical_error:306] CRITICAL_ERROR | _update_overview_rich_attempt_3 | AttributeError: 'ICTEnterpriseApp' object has no attribute '_get_system_stats'
[2025-08-09 16:21:31.111] [ICT_Dashboard_BlackBox_error] [CRITICAL] [log_critical_error:307] STACK_TRACE | Traceback (most recent call last):
  File "c:\Users\v_jac\Desktop\itc engine v5.0\ict-engine-v6.0-enterprise-sic\tests\ict_enterprise_dashboard_fixed.py", line 464, in _update_overview
    system_stats = self._get_system_stats()
                   ^^^^^^^^^^^^^^^^^^^^^^
AttributeError: 'ICTEnterpriseApp' object has no attribute '_get_system_stats'

[2025-08-09 16:21:31.122] [ICT_Dashboard_BlackBox_error] [CRITICAL] [log_critical_error:306] CRITICAL_ERROR | _update_overview_rich | AttributeError: 'ICTEnterpriseApp' object has no attribute '_get_system_stats'
[2025-08-09 16:21:31.132] [ICT_Dashboard_BlackBox_error] [CRITICAL] [log_critical_error:307] STACK_TRACE | Traceback (most recent call last):
  File "c:\Users\v_jac\Desktop\itc engine v5.0\ict-engine-v6.0-enterprise-sic\tests\ict_enterprise_dashboard_fixed.py", line 464, in _update_overview
    system_stats = self._get_system_stats()
                   ^^^^^^^^^^^^^^^^^^^^^^
AttributeError: 'ICTEnterpriseApp' object has no attribute '_get_system_stats'

[2025-08-09 16:21:32.069] [ICT_Dashboard_BlackBox_error] [CRITICAL] [log_critical_error:306] CRITICAL_ERROR | _update_overview_rich_attempt_1 | AttributeError: 'ICTEnterpriseApp' object has no attribute '_get_system_stats'
[2025-08-09 16:21:32.085] [ICT_Dashboard_BlackBox_error] [CRITICAL] [log_critical_error:307] STACK_TRACE | Traceback (most recent call last):
  File "c:\Users\v_jac\Desktop\itc engine v5.0\ict-engine-v6.0-enterprise-sic\tests\ict_enterprise_dashboard_fixed.py", line 464, in _update_overview
    system_stats = self._get_system_stats()
                   ^^^^^^^^^^^^^^^^^^^^^^
AttributeError: 'ICTEnterpriseApp' object has no attribute '_get_system_stats'

[2025-08-09 16:21:32.096] [ICT_Dashboard_BlackBox_error] [CRITICAL] [log_critical_error:306] CRITICAL_ERROR | _update_overview_rich_attempt_2 | AttributeError: 'ICTEnterpriseApp' object has no attribute '_get_system_stats'
[2025-08-09 16:21:32.105] [ICT_Dashboard_BlackBox_error] [CRITICAL] [log_critical_error:307] STACK_TRACE | Traceback (most recent call last):
  File "c:\Users\v_jac\Desktop\itc engine v5.0\ict-engine-v6.0-enterprise-sic\tests\ict_enterprise_dashboard_fixed.py", line 464, in _update_overview
    system_stats = self._get_system_stats()
                   ^^^^^^^^^^^^^^^^^^^^^^
AttributeError: 'ICTEnterpriseApp' object has no attribute '_get_system_stats'

[2025-08-09 16:21:32.115] [ICT_Dashboard_BlackBox_error] [CRITICAL] [log_critical_error:306] CRITICAL_ERROR | _update_overview_rich_attempt_3 | AttributeError: 'ICTEnterpriseApp' object has no attribute '_get_system_stats'
[2025-08-09 16:21:32.124] [ICT_Dashboard_BlackBox_error] [CRITICAL] [log_critical_error:307] STACK_TRACE | Traceback (most recent call last):
  File "c:\Users\v_jac\Desktop\itc engine v5.0\ict-engine-v6.0-enterprise-sic\tests\ict_enterprise_dashboard_fixed.py", line 464, in _update_overview
    system_stats = self._get_system_stats()
                   ^^^^^^^^^^^^^^^^^^^^^^
AttributeError: 'ICTEnterpriseApp' object has no attribute '_get_system_stats'

[2025-08-09 16:21:32.134] [ICT_Dashboard_BlackBox_error] [CRITICAL] [log_critical_error:306] CRITICAL_ERROR | _update_overview_rich | AttributeError: 'ICTEnterpriseApp' object has no attribute '_get_system_stats'
[2025-08-09 16:21:32.143] [ICT_Dashboard_BlackBox_error] [CRITICAL] [log_critical_error:307] STACK_TRACE | Traceback (most recent call last):
  File "c:\Users\v_jac\Desktop\itc engine v5.0\ict-engine-v6.0-enterprise-sic\tests\ict_enterprise_dashboard_fixed.py", line 464, in _update_overview
    system_stats = self._get_system_stats()
                   ^^^^^^^^^^^^^^^^^^^^^^
AttributeError: 'ICTEnterpriseApp' object has no attribute '_get_system_stats'

[2025-08-09 16:21:33.097] [ICT_Dashboard_BlackBox_error] [CRITICAL] [log_critical_error:306] CRITICAL_ERROR | _update_overview_rich_attempt_1 | AttributeError: 'ICTEnterpriseApp' object has no attribute '_get_system_stats'
[2025-08-09 16:21:33.107] [ICT_Dashboard_BlackBox_error] [CRITICAL] [log_critical_error:307] STACK_TRACE | Traceback (most recent call last):
  File "c:\Users\v_jac\Desktop\itc engine v5.0\ict-engine-v6.0-enterprise-sic\tests\ict_enterprise_dashboard_fixed.py", line 464, in _update_overview
    system_stats = self._get_system_stats()
                   ^^^^^^^^^^^^^^^^^^^^^^
AttributeError: 'ICTEnterpriseApp' object has no attribute '_get_system_stats'

[2025-08-09 16:21:33.117] [ICT_Dashboard_BlackBox_error] [CRITICAL] [log_critical_error:306] CRITICAL_ERROR | _update_overview_rich_attempt_2 | AttributeError: 'ICTEnterpriseApp' object has no attribute '_get_system_stats'
[2025-08-09 16:21:33.127] [ICT_Dashboard_BlackBox_error] [CRITICAL] [log_critical_error:307] STACK_TRACE | Traceback (most recent call last):
  File "c:\Users\v_jac\Desktop\itc engine v5.0\ict-engine-v6.0-enterprise-sic\tests\ict_enterprise_dashboard_fixed.py", line 464, in _update_overview
    system_stats = self._get_system_stats()
                   ^^^^^^^^^^^^^^^^^^^^^^
AttributeError: 'ICTEnterpriseApp' object has no attribute '_get_system_stats'

[2025-08-09 16:21:33.136] [ICT_Dashboard_BlackBox_error] [CRITICAL] [log_critical_error:306] CRITICAL_ERROR | _update_overview_rich_attempt_3 | AttributeError: 'ICTEnterpriseApp' object has no attribute '_get_system_stats'
[2025-08-09 16:21:33.147] [ICT_Dashboard_BlackBox_error] [CRITICAL] [log_critical_error:307] STACK_TRACE | Traceback (most recent call last):
  File "c:\Users\v_jac\Desktop\itc engine v5.0\ict-engine-v6.0-enterprise-sic\tests\ict_enterprise_dashboard_fixed.py", line 464, in _update_overview
    system_stats = self._get_system_stats()
                   ^^^^^^^^^^^^^^^^^^^^^^
AttributeError: 'ICTEnterpriseApp' object has no attribute '_get_system_stats'

[2025-08-09 16:21:33.160] [ICT_Dashboard_BlackBox_error] [CRITICAL] [log_critical_error:306] CRITICAL_ERROR | _update_overview_rich | AttributeError: 'ICTEnterpriseApp' object has no attribute '_get_system_stats'
[2025-08-09 16:21:33.169] [ICT_Dashboard_BlackBox_error] [CRITICAL] [log_critical_error:307] STACK_TRACE | Traceback (most recent call last):
  File "c:\Users\v_jac\Desktop\itc engine v5.0\ict-engine-v6.0-enterprise-sic\tests\ict_enterprise_dashboard_fixed.py", line 464, in _update_overview
    system_stats = self._get_system_stats()
                   ^^^^^^^^^^^^^^^^^^^^^^
AttributeError: 'ICTEnterpriseApp' object has no attribute '_get_system_stats'

[2025-08-09 16:21:34.070] [ICT_Dashboard_BlackBox_error] [CRITICAL] [log_critical_error:306] CRITICAL_ERROR | _update_overview_rich_attempt_1 | AttributeError: 'ICTEnterpriseApp' object has no attribute '_get_system_stats'
[2025-08-09 16:21:34.085] [ICT_Dashboard_BlackBox_error] [CRITICAL] [log_critical_error:307] STACK_TRACE | Traceback (most recent call last):
  File "c:\Users\v_jac\Desktop\itc engine v5.0\ict-engine-v6.0-enterprise-sic\tests\ict_enterprise_dashboard_fixed.py", line 464, in _update_overview
    system_stats = self._get_system_stats()
                   ^^^^^^^^^^^^^^^^^^^^^^
AttributeError: 'ICTEnterpriseApp' object has no attribute '_get_system_stats'

[2025-08-09 16:21:34.095] [ICT_Dashboard_BlackBox_error] [CRITICAL] [log_critical_error:306] CRITICAL_ERROR | _update_overview_rich_attempt_2 | AttributeError: 'ICTEnterpriseApp' object has no attribute '_get_system_stats'
[2025-08-09 16:21:34.106] [ICT_Dashboard_BlackBox_error] [CRITICAL] [log_critical_error:307] STACK_TRACE | Traceback (most recent call last):
  File "c:\Users\v_jac\Desktop\itc engine v5.0\ict-engine-v6.0-enterprise-sic\tests\ict_enterprise_dashboard_fixed.py", line 464, in _update_overview
    system_stats = self._get_system_stats()
                   ^^^^^^^^^^^^^^^^^^^^^^
AttributeError: 'ICTEnterpriseApp' object has no attribute '_get_system_stats'

[2025-08-09 16:21:34.120] [ICT_Dashboard_BlackBox_error] [CRITICAL] [log_critical_error:306] CRITICAL_ERROR | _update_overview_rich_attempt_3 | AttributeError: 'ICTEnterpriseApp' object has no attribute '_get_system_stats'
[2025-08-09 16:21:34.134] [ICT_Dashboard_BlackBox_error] [CRITICAL] [log_critical_error:307] STACK_TRACE | Traceback (most recent call last):
  File "c:\Users\v_jac\Desktop\itc engine v5.0\ict-engine-v6.0-enterprise-sic\tests\ict_enterprise_dashboard_fixed.py", line 464, in _update_overview
    system_stats = self._get_system_stats()
                   ^^^^^^^^^^^^^^^^^^^^^^
AttributeError: 'ICTEnterpriseApp' object has no attribute '_get_system_stats'

[2025-08-09 16:21:34.143] [ICT_Dashboard_BlackBox_error] [CRITICAL] [log_critical_error:306] CRITICAL_ERROR | _update_overview_rich | AttributeError: 'ICTEnterpriseApp' object has no attribute '_get_system_stats'
[2025-08-09 16:21:34.153] [ICT_Dashboard_BlackBox_error] [CRITICAL] [log_critical_error:307] STACK_TRACE | Traceback (most recent call last):
  File "c:\Users\v_jac\Desktop\itc engine v5.0\ict-engine-v6.0-enterprise-sic\tests\ict_enterprise_dashboard_fixed.py", line 464, in _update_overview
    system_stats = self._get_system_stats()
                   ^^^^^^^^^^^^^^^^^^^^^^
AttributeError: 'ICTEnterpriseApp' object has no attribute '_get_system_stats'

