[2025-08-09 15:59:43.620] [ICT_Dashboard_BlackBox_error] [CRITICAL] [log_critical_error:306] CRITICAL_ERROR | Test context | ValueError: Test error for BlackBox
[2025-08-09 15:59:43.620] [ICT_Dashboard_BlackBox_error] [CRITICAL] [log_critical_error:307] STACK_TRACE | Traceback (most recent call last):
  File "c:\Users\v_jac\Desktop\itc engine v5.0\ict-engine-v6.0-enterprise-sic\tests\ict_dashboard_blackbox_logger.py", line 503, in <module>
    raise ValueError("Test error for BlackBox")
ValueError: Test error for BlackBox

